Workbook
Name EQUIPLIST: 'EQUIPMENT REGISTER'!$B$7:$B$21
Name MECHLIST: 'SETUP & TARGETS'!$B$40:$B$43

Sheet DASHBOARD
B2: RCPM GGV PLANT OPTIMIZATION PLANNER
B87: Fleet utilisation | E87: Fleet availability | H87: Machines on target | K87: Total actual hours | N87: Total delay hours
B88: ='FLEET SUMMARY'!H12 -> 0.22616487 | E88: ='FLEET SUMMARY'!J12 -> 0.62740741 | H88: =COUNTIF('FLEET SUMMARY'!M7:M11,"ON TARGET") -> 0 | K88: ='FLEET SUMMARY'!E12 -> 631 | N88: ='FLEET SUMMARY'!K12+'FLEET SUMMARY'!L12 -> 723

Sheet INFO - MECHANICAL
B2: HOW THE MECHANICAL MODULE WORKS
B3: Exxaro Grootegeluk | PLANT OPTIMIZATION
C5: What the module answers
C7: Are the GG mechanics being effectively utilised, are they executing planned maintenance and repairs within the expected time, and is their performance improving equipment availability and returning equipment to production?
C8: The chain
C10: MECHANIC > SHIFT > EQUIPMENT > ACTIVITY > TIME SPENT > PLANNED TIME > RESULT > AVAILABILITY AND UTILISATION. Every dashboard KPI can be traced back down that chain to a single line on the MAINTENANCE LOG.
C11: Where you capture
C13: • MECHANIC ROSTER - shift letter (D, N or O) and hours on site, per mechanic per day.
C14: • EQUIPMENT REGISTER - location, project, status, breakdown reason, last inspection, last service and next service date, for every machine including parked ones.
C15: • MAINTENANCE LOG - one line per job: machine, activity, mechanic, assistant, breakdown and repair times, planned hours, ETR, actual completion, return to service and status.
C16: • AVAILABILITY (rental block) - planned, other downtime and operating hours for the machines that have no daily machine tab.
C17: Where you do not capture
C19: The DASHBOARD, MECHANIC PERFORMANCE and the summary blocks are calculated. Nothing is typed there, so no one can enter a figure that misrepresents performance.
C20: How the measures are built
... C32: Run down the DATA QUALITY CHECK tab. Every line there should read OK.
D38: GG MECHANICAL TEAM, EQUIPMENT & MAINTENANCE
D39: Read only - every figure is calculated from the MECHANIC ROSTER, the EQUIPMENT REGISTER and the MAINTENANCE LOG
D41: A. WORKFORCE
D42: Mechanics scheduled | G42: Mechanics present | J42: Hours on site | M42: Productive hours | P42: Labour utilisation
D43: =COUNTA('SETUP & TARGETS'!$B$40:$B$43) -> 4 | G43: =COUNTIF('MECHANIC PERFORMANCE'!E7:E10,">0") -> 0 | J43: ='MECHANIC PERFORMANCE'!E11 -> 0 | M43: ='MECHANIC PERFORMANCE'!G11 -> 264 | P43: ='MECHANIC PERFORMANCE'!H11 -> 0
D45: B. EQUIPMENT
D46: Equipment on register | G46: Active | J46: Inactive | M46: Available | P46: Unavailable
D47: ='EQUIPMENT REGISTER'!C24 -> 0 | G47: ='EQUIPMENT REGISTER'!C25 -> 0 | J47: ='EQUIPMENT REGISTER'!C26 -> 0 | M47: ='EQUIPMENT REGISTER'!C27 -> 0 | P47: ='EQUIPMENT REGISTER'!C28 -> 0
D48: Prod fleet availability | G48: Prod fleet utilisation | J48: Rental availability | M48: Rental utilisation | P48: Machines with open jobs
D49: ='FLEET SUMMARY'!J12 -> 0.62740741 | G49: ='FLEET SUMMARY'!H12 -> 0.22616487 | J49: =AVAILABILITY!J22 -> 0 | M49: =AVAILABILITY!M22 -> 0 | P49: =COUNTIF('EQUIPMENT REGISTER'!T7:T21,">0") -> 1
D51: C. MAINTENANCE
D52: Open breakdowns | G52: Completed repairs | J52: Planned maint completed | M52: Overdue maintenance | P52: Maintenance backlog
D53: ='MECHANIC PERFORMANCE'!C63 -> 1 | G53: ='MECHANIC PERFORMANCE'!C64 -> 0 | J53: ='MECHANIC PERFORMANCE'!C65 -> 0 | M53: ='EQUIPMENT REGISTER'!C29 -> 0 | P53: ='EQUIPMENT REGISTER'!C31 -> 0
D55: D. MECHANICAL EFFECTIVENESS
D56: MTTR (hrs) | G56: Planned repair hrs | J56: Actual repair hrs | M56: Avg repair variance (hrs) | P56: ETR compliance
D57: ='MECHANIC PERFORMANCE'!C69 -> 0 | G57: ='MECHANIC PERFORMANCE'!C66 -> 6 | J57: ='MECHANIC PERFORMANCE'!C67 -> 132 | M57: ='MECHANIC PERFORMANCE'!C68 -> 0 | P57: ='MECHANIC PERFORMANCE'!C72 -> 1
D58: Jobs completed on time | G58: Jobs overdue | J58: Repeat breakdowns | M58: Returned to production | P58: Machines flagged red
D59: ='MECHANIC PERFORMANCE'!C70 -> 1 | G59: ='MECHANIC PERFORMANCE'!C71 -> 0 | J59: ='MECHANIC PERFORMANCE'!C73 -> 0 | M59: ='MECHANIC PERFORMANCE'!C74 -> 0 | P59: =COUNTIF('EQUIPMENT REGISTER'!V7:V21,"RED") -> 3

Sheet FLEET SUMMARY
B2: FLEET SUMMARY
B3: Exxaro Grootegeluk | PLANT OPTIMIZATION
B4: All figures calculated from the machine tabs. Nothing is captured on this sheet.
B6: EQUIP | C6: MACHINE TYPE | D6: PLANNED HRS | E6: ACTUAL HRS | F6: HRS GAP | G6: UTIL TARGET | H6: ACTUAL UTIL | I6: AVAIL TARGET | J6: ACTUAL AVAIL | K6: OPS DELAY HRS | L6: B/DOWN HRS | M6: STATUS
B7: CRT220 | C7: CAT 773 RDT | D7: ='CRT220'!K38 -> 558 | E7: ='CRT220'!F38 -> 0 | F7: =E7-D7 -> -558 | G7: ='SETUP & TARGETS'!$C11 -> 0.8 | H7: =IFERROR(E7/D7,0) -> 0 | I7: ='SETUP & TARGETS'!$C12 -> 0.85 | J7: ='CRT220'!O38 -> 0 | K7: ='CRT220'!H38 -> 0 | L7: ='CRT220'!I38 -> 270 | M7: =IF(H7>=G7,"ON TARGET",IF(H7>='SETUP & TARGETS'!$C13,"NEAR TARGET","BELOW TARGET")) -> BELOW TARGET
B8: CRT221 | C8: CAT 773 RDT | D8: ='CRT221'!K38 -> 558 | E8: ='CRT221'!F38 -> 164 | F8: =E8-D8 -> -394 | G8: ='SETUP & TARGETS'!$C11 -> 0.8 | H8: =IFERROR(E8/D8,0) -> 0.29390681 | I8: ='SETUP & TARGETS'!$C12 -> 0.85 | J8: ='CRT221'!O38 -> 0.71481481 | K8: ='CRT221'!H38 -> 29 | L8: ='CRT221'!I38 -> 77 | M8: =IF(H8>=G8,"ON TARGET",IF(H8>='SETUP & TARGETS'!$C13,"NEAR TARGET","BELOW TARGET")) -> BELOW TARGET
B9: CRT222 | C9: CAT 773 RDT | D9: ='CRT222'!K38 -> 558 | E9: ='CRT222'!F38 -> 113 | F9: =E9-D9 -> -445 | G9: ='SETUP & TARGETS'!$C11 -> 0.8 | H9: =IFERROR(E9/D9,0) -> 0.20250896 | I9: ='SETUP & TARGETS'!$C12 -> 0.85 | J9: ='CRT222'!O38 -> 0.46296296 | K9: ='CRT222'!H38 -> 13 | L9: ='CRT222'!I38 -> 145 | M9: =IF(H9>=G9,"ON TARGET",IF(H9>='SETUP & TARGETS'!$C13,"NEAR TARGET","BELOW TARGET")) -> BELOW TARGET
B10: CRT224 | C10: CAT 395 Excavator | D10: ='CRT224'!K38 -> 558 | E10: ='CRT224'!F38 -> 231 | F10: =E10-D10 -> -327 | G10: ='SETUP & TARGETS'!$C11 -> 0.8 | H10: =IFERROR(E10/D10,0) -> 0.41397849 | I10: ='SETUP & TARGETS'!$C12 -> 0.85 | J10: ='CRT224'!O38 -> 0.95925926 | K10: ='CRT224'!H38 -> 35 | L10: ='CRT224'!I38 -> 11 | M10: =IF(H10>=G10,"ON TARGET",IF(H10>='SETUP & TARGETS'!$C13,"NEAR TARGET","BELOW TARGET")) -> BELOW TARGET
B11: CRT225 | C11: CAT D9 Dozer | D11: ='CRT225'!K38 -> 558 | E11: ='CRT225'!F38 -> 123 | F11: =E11-D11 -> -435 | G11: ='SETUP & TARGETS'!$C11 -> 0.8 | H11: =IFERROR(E11/D11,0) -> 0.22043011 | I11: ='SETUP & TARGETS'!$C12 -> 0.85 | J11: ='CRT225'!O38 -> 1 | K11: ='CRT225'!H38 -> 143 | L11: ='CRT225'!I38 -> 0 | M11: =IF(H11>=G11,"ON TARGET",IF(H11>='SETUP & TARGETS'!$C13,"NEAR TARGET","BELOW TARGET")) -> BELOW TARGET
B12: FLEET TOTAL | D12: =SUM(D7:D11) -> 2790 | E12: =SUM(E7:E11) -> 631 | F12: =SUM(F7:F11) -> -2159 | G12: ='SETUP & TARGETS'!$C11 -> 0.8 | H12: =IFERROR(E12/D12,0) -> 0.22616487 | I12: ='SETUP & TARGETS'!$C12 -> 0.85 | J12: =IFERROR(AVERAGE(J7:J11),0) -> 0.62740741 | K12: =SUM(K7:K11) -> 220 | L12: =SUM(L7:L11) -> 503
B14: CHART DATA - do not edit
B15: EQUIP | C15: ACHIEVED | D15: SHORTFALL | E15: AVAIL ACHIEVED | F15: AVAIL SHORTFALL
B16: =B7 -> CRT220 | C16: =MIN(1,H7) -> 0 | D16: =MAX(0,1-H7) -> 1 | E16: =MIN(1,J7) -> 0 | F16: =MAX(0,1-J7) -> 1
B17: =B8 -> CRT221 | C17: =MIN(1,H8) -> 0.29390681 | D17: =MAX(0,1-H8) -> 0.70609319 | E17: =MIN(1,J8) -> 0.71481481 | F17: =MAX(0,1-J8) -> 0.28518519
B18: =B9 -> CRT222 | C18: =MIN(1,H9) -> 0.20250896 | D18: =MAX(0,1-H9) -> 0.79749104 | E18: =MIN(1,J9) -> 0.46296296 | F18: =MAX(0,1-J9) -> 0.53703704
B19: =B10 -> CRT224 | C19: =MIN(1,H10) -> 0.41397849 | D19: =MAX(0,1-H10) -> 0.58602151 | E19: =MIN(1,J10) -> 0.95925926 | F19: =MAX(0,1-J10) -> 0.040740741
B20: =B11 -> CRT225 | C20: =MIN(1,H11) -> 0.22043011 | D20: =MAX(0,1-H11) -> 0.77956989 | E20: =MIN(1,J11) -> 1 | F20: =MAX(0,1-J11) -> 0
B22: CUMULATIVE FLEET TREND - do not edit
B23: DAY | C23: CUM TARGET | D23: CUM ACTUAL
B24: 1 | C24: ='CRT220'!K7+'CRT221'!K7+'CRT222'!K7+'CRT224'!K7+'CRT225'!K7 -> 90 | D24: ='CRT220'!L7+'CRT221'!L7+'CRT222'!L7+'CRT224'!L7+'CRT225'!L7 -> 35
B25: 2 | C25: ='CRT220'!K8+'CRT221'!K8+'CRT222'!K8+'CRT224'!K8+'CRT225'!K8 -> 180 | D25: ='CRT220'!L8+'CRT221'!L8+'CRT222'!L8+'CRT224'!L8+'CRT225'!L8 -> 70
B26: 3 | C26: ='CRT220'!K9+'CRT221'!K9+'CRT222'!K9+'CRT224'!K9+'CRT225'!K9 -> 270 | D26: ='CRT220'!L9+'CRT221'!L9+'CRT222'!L9+'CRT224'!L9+'CRT225'!L9 -> 103
B27: 4 | C27: ='CRT220'!K10+'CRT221'!K10+'CRT222'!K10+'CRT224'!K10+'CRT225'!K10 -> 360 | D27: ='CRT220'!L10+'CRT221'!L10+'CRT222'!L10+'CRT224'!L10+'CRT225'!L10 -> 129
B28: 5 | C28: ='CRT220'!K11+'CRT221'!K11+'CRT222'!K11+'CRT224'!K11+'CRT225'!K11 -> 450 | D28: ='CRT220'!L11+'CRT221'!L11+'CRT222'!L11+'CRT224'!L11+'CRT225'!L11 -> 185
B29: 6 | C29: ='CRT220'!K12+'CRT221'!K12+'CRT222'!K12+'CRT224'!K12+'CRT225'!K12 -> 540 | D29: ='CRT220'!L12+'CRT221'!L12+'CRT222'!L12+'CRT224'!L12+'CRT225'!L12 -> 214
B30: 7 | C30: ='CRT220'!K13+'CRT221'!K13+'CRT222'!K13+'CRT224'!K13+'CRT225'!K13 -> 630 | D30: ='CRT220'!L13+'CRT221'!L13+'CRT222'!L13+'CRT224'!L13+'CRT225'!L13 -> 245
B31: 8 | C31: ='CRT220'!K14+'CRT221'!K14+'CRT222'!K14+'CRT224'!K14+'CRT225'!K14 -> 720 | D31: ='CRT220'!L14+'CRT221'!L14+'CRT222'!L14+'CRT224'!L14+'CRT225'!L14 -> 277
B32: 9 | C32: ='CRT220'!K15+'CRT221'!K15+'CRT222'!K15+'CRT224'!K15+'CRT225'!K15 -> 810 | D32: ='CRT220'!L15+'CRT221'!L15+'CRT222'!L15+'CRT224'!L15+'CRT225'!L15 -> 330
B33: 10 | C33: ='CRT220'!K16+'CRT221'!K16+'CRT222'!K16+'CRT224'!K16+'CRT225'!K16 -> 900 | D33: ='CRT220'!L16+'CRT221'!L16+'CRT222'!L16+'CRT224'!L16+'CRT225'!L16 -> 365
B34: 11 | C34: ='CRT220'!K17+'CRT221'!K17+'CRT222'!K17+'CRT224'!K17+'CRT225'!K17 -> 990 | D34: ='CRT220'!L17+'CRT221'!L17+'CRT222'!L17+'CRT224'!L17+'CRT225'!L17 -> 410
B35: 12 | C35: ='CRT220'!K18+'CRT221'!K18+'CRT222'!K18+'CRT224'!K18+'CRT225'!K18 -> 1080 | D35: ='CRT220'!L18+'CRT221'!L18+'CRT222'!L18+'CRT224'!L18+'CRT225'!L18 -> 453
... B54: 31 | C54: ='CRT220'!K37+'CRT221'!K37+'CRT222'!K37+'CRT224'!K37+'CRT225'!K37 -> 2790 | D54: ='CRT220'!L37+'CRT221'!L37+'CRT222'!L37+'CRT224'!L37+'CRT225'!L37 -> 631

Sheet MECHANIC PERFORMANCE
B2: MECHANIC PRODUCTIVITY & EFFECTIVENESS
B3: Exxaro Grootegeluk | PLANT OPTIMIZATION
B4: Effectiveness is measured on execution of planned work and the return of equipment to production - not on attendance and not on the absence of breakdowns. Every figure on this sheet is calculated from the MECHANIC ROSTER and the MAINTENANCE LOG.
B6: MECHANIC | C6: POSITION | D6: SCHED HRS | E6: HRS ON SITE | F6: ATTEND % | G6: PRODUCTIVE HRS | H6: LABOUR UTIL % | I6: JOBS ASSIGNED | J6: JOBS COMPLETED | K6: PLANNED REPAIR HRS | L6: ACTUAL REPAIR HRS | M6: VARIANCE HRS | N6: MTTR (HRS) | O6: ETR MET | P6: ETR COMPLIANCE % | Q6: JOBS OVERDUE | R6: EQUIP RETURNED TO PRODUCTION | S6: REPEAT B/DOWNS | T6: RAG
B7: ='SETUP & TARGETS'!$B$40 -> Lindokuhle Ntombela | C7: ='SETUP & TARGETS'!$C$40 -> Mechanic / Acting Team Leader | D7: ='MECHANIC ROSTER'!D39 -> 0 | E7: ='MECHANIC ROSTER'!E39 -> 0 | F7: =IFERROR($E7/$D7,0) -> 0 | G7: ='MECHANIC ROSTER'!F39 -> 132 | H7: =IFERROR($G7/$E7,0) -> 0 | I7: =COUNTIF('MAINTENANCE LOG'!$J$8:$J$107,$B7)+COUNTIF('MAINTENANCE LOG'!$K$8:$K$107,$B7) -> 1 | J7: =COUNTIFS('MAINTENANCE LOG'!$J$8:$J$107,$B7,'MAINTENANCE LOG'!$Z$8:$Z$107,"Completed") -> 0 | K7: =SUMIFS('MAINTENANCE LOG'!$O$8:$O$107,'MAINTENANCE LOG'!$J$8:$J$107,$B7) -> 6 | L7: =SUMIFS('MAINTENANCE LOG'!$R$8:$R$107,'MAINTENANCE LOG'!$J$8:$J$107,$B7) -> 132 | M7: =$L7-$K7 -> 126 | N7: =IFERROR(SUMIFS('MAINTENANCE LOG'!$R$8:$R$107,'MAINTENANCE LOG'!$J$8:$J$107,$B7,'MAINTENANCE LOG'!$Z$8:$Z$107,"Completed")/COUNTIFS('MAINTENANCE LOG'!$J$8:$J$107,$B7,'MAINTENANCE LOG'!$Z$8:$Z$107,"Completed"),0) -> 0 | O7: =COUNTIFS('MAINTENANCE LOG'!$J$8:$J$107,$B7,'MAINTENANCE LOG'!$U$8:$U$107,"MET") -> 1 | P7: =IFERROR($O7/$J7,0) -> 0 | Q7: =COUNTIFS('MAINTENANCE LOG'!$J$8:$J$107,$B7,'MAINTENANCE LOG'!$U$8:$U$107,"MISSED")+COUNTIFS('MAINTENANCE LOG'!$J$8:$J$107,$B7,'MAINTENANCE LOG'!$U$8:$U$107,"OVERDUE") -> 0 | R7: =COUNTIFS('MAINTENANCE LOG'!$J$8:$J$107,$B7,'MAINTENANCE LOG'!$X$8:$X$107,"Y") -> 0 | S7: =COUNTIFS('MAINTENANCE LOG'!$J$8:$J$107,$B7,'MAINTENANCE LOG'!$AA$8:$AA$107,"REPEAT") -> 0 | T7: =IF($I7=0,"",IF($J7=0,IF($H7>='SETUP & TARGETS'!$C$29,"GREEN","AMBER"),IF(OR($P7<'SETUP & TARGETS'!$C$30*0.8,$Q7>0),"RED",IF(AND($H7>='SETUP & TARGETS'!$C$29,$P7>='SETUP & TARGETS'!$C$30),"GREEN","AMBER")))) -> AMBER
B8: ='SETUP & TARGETS'!$B$41 -> Motlalepula Molefe | C8: ='SETUP & TARGETS'!$C$41 -> Mechanic | D8: ='MECHANIC ROSTER'!H39 -> 0 | E8: ='MECHANIC ROSTER'!I39 -> 0 | F8: =IFERROR($E8/$D8,0) -> 0 | G8: ='MECHANIC ROSTER'!J39 -> 0 | H8: =IFERROR($G8/$E8,0) -> 0 | I8: =COUNTIF('MAINTENANCE LOG'!$J$8:$J$107,$B8)+COUNTIF('MAINTENANCE LOG'!$K$8:$K$107,$B8) -> 0 | J8: =COUNTIFS('MAINTENANCE LOG'!$J$8:$J$107,$B8,'MAINTENANCE LOG'!$Z$8:$Z$107,"Completed") -> 0 | K8: =SUMIFS('MAINTENANCE LOG'!$O$8:$O$107,'MAINTENANCE LOG'!$J$8:$J$107,$B8) -> 0 | L8: =SUMIFS('MAINTENANCE LOG'!$R$8:$R$107,'MAINTENANCE LOG'!$J$8:$J$107,$B8) -> 0 | M8: =$L8-$K8 -> 0 | N8: =IFERROR(SUMIFS('MAINTENANCE LOG'!$R$8:$R$107,'MAINTENANCE LOG'!$J$8:$J$107,$B8,'MAINTENANCE LOG'!$Z$8:$Z$107,"Completed")/COUNTIFS('MAINTENANCE LOG'!$J$8:$J$107,$B8,'MAINTENANCE LOG'!$Z$8:$Z$107,"Completed"),0) -> 0 | O8: =COUNTIFS('MAINTENANCE LOG'!$J$8:$J$107,$B8,'MAINTENANCE LOG'!$U$8:$U$107,"MET") -> 0 | P8: =IFERROR($O8/$J8,0) -> 0 | Q8: =COUNTIFS('MAINTENANCE LOG'!$J$8:$J$107,$B8,'MAINTENANCE LOG'!$U$8:$U$107,"MISSED")+COUNTIFS('MAINTENANCE LOG'!$J$8:$J$107,$B8,'MAINTENANCE LOG'!$U$8:$U$107,"OVERDUE") -> 0 | R8: =COUNTIFS('MAINTENANCE LOG'!$J$8:$J$107,$B8,'MAINTENANCE LOG'!$X$8:$X$107,"Y") -> 0 | S8: =COUNTIFS('MAINTENANCE LOG'!$J$8:$J$107,$B8,'MAINTENANCE LOG'!$AA$8:$AA$107,"REPEAT") -> 0 | T8: =IF($I8=0,"",IF($J8=0,IF($H8>='SETUP & TARGETS'!$C$29,"GREEN","AMBER"),IF(OR($P8<'SETUP & TARGETS'!$C$30*0.8,$Q8>0),"RED",IF(AND($H8>='SETUP & TARGETS'!$C$29,$P8>='SETUP & TARGETS'!$C$30),"GREEN","AMBER"))))
B9: ='SETUP & TARGETS'!$B$42 -> Thabo Monyane | C9: ='SETUP & TARGETS'!$C$42 -> Mechanic | D9: ='MECHANIC ROSTER'!L39 -> 0 | E9: ='MECHANIC ROSTER'!M39 -> 0 | F9: =IFERROR($E9/$D9,0) -> 0 | G9: ='MECHANIC ROSTER'!N39 -> 132 | H9: =IFERROR($G9/$E9,0) -> 0 | I9: =COUNTIF('MAINTENANCE LOG'!$J$8:$J$107,$B9)+COUNTIF('MAINTENANCE LOG'!$K$8:$K$107,$B9) -> 1 | J9: =COUNTIFS('MAINTENANCE LOG'!$J$8:$J$107,$B9,'MAINTENANCE LOG'!$Z$8:$Z$107,"Completed") -> 0 | K9: =SUMIFS('MAINTENANCE LOG'!$O$8:$O$107,'MAINTENANCE LOG'!$J$8:$J$107,$B9) -> 0 | L9: =SUMIFS('MAINTENANCE LOG'!$R$8:$R$107,'MAINTENANCE LOG'!$J$8:$J$107,$B9) -> 0 | M9: =$L9-$K9 -> 0 | N9: =IFERROR(SUMIFS('MAINTENANCE LOG'!$R$8:$R$107,'MAINTENANCE LOG'!$J$8:$J$107,$B9,'MAINTENANCE LOG'!$Z$8:$Z$107,"Completed")/COUNTIFS('MAINTENANCE LOG'!$J$8:$J$107,$B9,'MAINTENANCE LOG'!$Z$8:$Z$107,"Completed"),0) -> 0 | O9: =COUNTIFS('MAINTENANCE LOG'!$J$8:$J$107,$B9,'MAINTENANCE LOG'!$U$8:$U$107,"MET") -> 0 | P9: =IFERROR($O9/$J9,0) -> 0 | Q9: =COUNTIFS('MAINTENANCE LOG'!$J$8:$J$107,$B9,'MAINTENANCE LOG'!$U$8:$U$107,"MISSED")+COUNTIFS('MAINTENANCE LOG'!$J$8:$J$107,$B9,'MAINTENANCE LOG'!$U$8:$U$107,"OVERDUE") -> 0 | R9: =COUNTIFS('MAINTENANCE LOG'!$J$8:$J$107,$B9,'MAINTENANCE LOG'!$X$8:$X$107,"Y") -> 0 | S9: =COUNTIFS('MAINTENANCE LOG'!$J$8:$J$107,$B9,'MAINTENANCE LOG'!$AA$8:$AA$107,"REPEAT") -> 0 | T9: =IF($I9=0,"",IF($J9=0,IF($H9>='SETUP & TARGETS'!$C$29,"GREEN","AMBER"),IF(OR($P9<'SETUP & TARGETS'!$C$30*0.8,$Q9>0),"RED",IF(AND($H9>='SETUP & TARGETS'!$C$29,$P9>='SETUP & TARGETS'!$C$30),"GREEN","AMBER")))) -> AMBER
B10: ='SETUP & TARGETS'!$B$43 -> Tshepang Maepa | C10: ='SETUP & TARGETS'!$C$43 -> Assistant Mechanic | D10: ='MECHANIC ROSTER'!P39 -> 0 | E10: ='MECHANIC ROSTER'!Q39 -> 0 | F10: =IFERROR($E10/$D10,0) -> 0 | G10: ='MECHANIC ROSTER'!R39 -> 0 | H10: =IFERROR($G10/$E10,0) -> 0 | I10: =COUNTIF('MAINTENANCE LOG'!$J$8:$J$107,$B10)+COUNTIF('MAINTENANCE LOG'!$K$8:$K$107,$B10) -> 0 | J10: =COUNTIFS('MAINTENANCE LOG'!$J$8:$J$107,$B10,'MAINTENANCE LOG'!$Z$8:$Z$107,"Completed") -> 0 | K10: =SUMIFS('MAINTENANCE LOG'!$O$8:$O$107,'MAINTENANCE LOG'!$J$8:$J$107,$B10) -> 0 | L10: =SUMIFS('MAINTENANCE LOG'!$R$8:$R$107,'MAINTENANCE LOG'!$J$8:$J$107,$B10) -> 0 | M10: =$L10-$K10 -> 0 | N10: =IFERROR(SUMIFS('MAINTENANCE LOG'!$R$8:$R$107,'MAINTENANCE LOG'!$J$8:$J$107,$B10,'MAINTENANCE LOG'!$Z$8:$Z$107,"Completed")/COUNTIFS('MAINTENANCE LOG'!$J$8:$J$107,$B10,'MAINTENANCE LOG'!$Z$8:$Z$107,"Completed"),0) -> 0 | O10: =COUNTIFS('MAINTENANCE LOG'!$J$8:$J$107,$B10,'MAINTENANCE LOG'!$U$8:$U$107,"MET") -> 0 | P10: =IFERROR($O10/$J10,0) -> 0 | Q10: =COUNTIFS('MAINTENANCE LOG'!$J$8:$J$107,$B10,'MAINTENANCE LOG'!$U$8:$U$107,"MISSED")+COUNTIFS('MAINTENANCE LOG'!$J$8:$J$107,$B10,'MAINTENANCE LOG'!$U$8:$U$107,"OVERDUE") -> 0 | R10: =COUNTIFS('MAINTENANCE LOG'!$J$8:$J$107,$B10,'MAINTENANCE LOG'!$X$8:$X$107,"Y") -> 0 | S10: =COUNTIFS('MAINTENANCE LOG'!$J$8:$J$107,$B10,'MAINTENANCE LOG'!$AA$8:$AA$107,"REPEAT") -> 0 | T10: =IF($I10=0,"",IF($J10=0,IF($H10>='SETUP & TARGETS'!$C$29,"GREEN","AMBER"),IF(OR($P10<'SETUP & TARGETS'!$C$30*0.8,$Q10>0),"RED",IF(AND($H10>='SETUP & TARGETS'!$C$29,$P10>='SETUP & TARGETS'!$C$30),"GREEN","AMBER"))))
B11: TEAM TOTAL | D11: =SUM(D7:D10) -> 0 | E11: =SUM(E7:E10) -> 0 | F11: =IFERROR($E11/$D11,0) -> 0 | G11: =SUM(G7:G10) -> 264 | H11: =IFERROR($G11/$E11,0) -> 0 | I11: =SUM(I7:I10) -> 2 | J11: =SUM(J7:J10) -> 0 | K11: =SUM(K7:K10) -> 6 | L11: =SUM(L7:L10) -> 132 | M11: =SUM(M7:M10) -> 126 | N11: =IFERROR($L11/$J11,0) -> 0 | O11: =SUM(O7:O10) -> 1 | P11: =IFERROR($O11/$J11,0) -> 0 | Q11: =SUM(Q7:Q10) -> 0 | R11: =SUM(R7:R10) -> 0 | S11: =SUM(S7:S10) -> 0
B13: MTTR BY EQUIPMENT
B14: EQUIP | C14: EQUIPMENT TYPE | D14: COMPLETED REPAIRS | E14: TOTAL REPAIR HRS | F14: MTTR (HRS) | G14: PLANNED HRS | H14: VARIANCE HRS | I14: REPEAT B/DOWNS
B15: ='EQUIPMENT REGISTER'!$B$7 -> CRT220 | C15: ='EQUIPMENT REGISTER'!$C$7 -> CAT 773 RDT | D15: =IF($B15="","",COUNTIFS('MAINTENANCE LOG'!$C$8:$C$107,$B15,'MAINTENANCE LOG'!$Z$8:$Z$107,"Completed")) -> 0 | E15: =IF($B15="","",SUMIFS('MAINTENANCE LOG'!$R$8:$R$107,'MAINTENANCE LOG'!$C$8:$C$107,$B15,'MAINTENANCE LOG'!$Z$8:$Z$107,"Completed")) -> 0 | F15: =IF($B15="","",IFERROR($E15/$D15,0)) -> 0 | G15: =IF($B15="","",SUMIFS('MAINTENANCE LOG'!$O$8:$O$107,'MAINTENANCE LOG'!$C$8:$C$107,$B15)) -> 6 | H15: =IF($B15="","",$E15-$G15) -> -6 | I15: =IF($B15="","",COUNTIFS('MAINTENANCE LOG'!$C$8:$C$107,$B15,'MAINTENANCE LOG'!$AA$8:$AA$107,"REPEAT")) -> 0
B16: ='EQUIPMENT REGISTER'!$B$8 -> CRT221 | C16: ='EQUIPMENT REGISTER'!$C$8 -> CAT 773 RDT | D16: =IF($B16="","",COUNTIFS('MAINTENANCE LOG'!$C$8:$C$107,$B16,'MAINTENANCE LOG'!$Z$8:$Z$107,"Completed")) -> 0 | E16: =IF($B16="","",SUMIFS('MAINTENANCE LOG'!$R$8:$R$107,'MAINTENANCE LOG'!$C$8:$C$107,$B16,'MAINTENANCE LOG'!$Z$8:$Z$107,"Completed")) -> 0 | F16: =IF($B16="","",IFERROR($E16/$D16,0)) -> 0 | G16: =IF($B16="","",SUMIFS('MAINTENANCE LOG'!$O$8:$O$107,'MAINTENANCE LOG'!$C$8:$C$107,$B16)) -> 0 | H16: =IF($B16="","",$E16-$G16) -> 0 | I16: =IF($B16="","",COUNTIFS('MAINTENANCE LOG'!$C$8:$C$107,$B16,'MAINTENANCE LOG'!$AA$8:$AA$107,"REPEAT")) -> 0
B17: ='EQUIPMENT REGISTER'!$B$9 -> CRT222 | C17: ='EQUIPMENT REGISTER'!$C$9 -> CAT 773 RDT | D17: =IF($B17="","",COUNTIFS('MAINTENANCE LOG'!$C$8:$C$107,$B17,'MAINTENANCE LOG'!$Z$8:$Z$107,"Completed")) -> 0 | E17: =IF($B17="","",SUMIFS('MAINTENANCE LOG'!$R$8:$R$107,'MAINTENANCE LOG'!$C$8:$C$107,$B17,'MAINTENANCE LOG'!$Z$8:$Z$107,"Completed")) -> 0 | F17: =IF($B17="","",IFERROR($E17/$D17,0)) -> 0 | G17: =IF($B17="","",SUMIFS('MAINTENANCE LOG'!$O$8:$O$107,'MAINTENANCE LOG'!$C$8:$C$107,$B17)) -> 0 | H17: =IF($B17="","",$E17-$G17) -> 0 | I17: =IF($B17="","",COUNTIFS('MAINTENANCE LOG'!$C$8:$C$107,$B17,'MAINTENANCE LOG'!$AA$8:$AA$107,"REPEAT")) -> 0
B18: ='EQUIPMENT REGISTER'!$B$10 -> CRT224 | C18: ='EQUIPMENT REGISTER'!$C$10 -> CAT 395 Excavator | D18: =IF($B18="","",COUNTIFS('MAINTENANCE LOG'!$C$8:$C$107,$B18,'MAINTENANCE LOG'!$Z$8:$Z$107,"Completed")) -> 0 | E18: =IF($B18="","",SUMIFS('MAINTENANCE LOG'!$R$8:$R$107,'MAINTENANCE LOG'!$C$8:$C$107,$B18,'MAINTENANCE LOG'!$Z$8:$Z$107,"Completed")) -> 0 | F18: =IF($B18="","",IFERROR($E18/$D18,0)) -> 0 | G18: =IF($B18="","",SUMIFS('MAINTENANCE LOG'!$O$8:$O$107,'MAINTENANCE LOG'!$C$8:$C$107,$B18)) -> 0 | H18: =IF($B18="","",$E18-$G18) -> 0 | I18: =IF($B18="","",COUNTIFS('MAINTENANCE LOG'!$C$8:$C$107,$B18,'MAINTENANCE LOG'!$AA$8:$AA$107,"REPEAT")) -> 0
B19: ='EQUIPMENT REGISTER'!$B$11 -> CRT225 | C19: ='EQUIPMENT REGISTER'!$C$11 -> CAT D9 Dozer | D19: =IF($B19="","",COUNTIFS('MAINTENANCE LOG'!$C$8:$C$107,$B19,'MAINTENANCE LOG'!$Z$8:$Z$107,"Completed")) -> 0 | E19: =IF($B19="","",SUMIFS('MAINTENANCE LOG'!$R$8:$R$107,'MAINTENANCE LOG'!$C$8:$C$107,$B19,'MAINTENANCE LOG'!$Z$8:$Z$107,"Completed")) -> 0 | F19: =IF($B19="","",IFERROR($E19/$D19,0)) -> 0 | G19: =IF($B19="","",SUMIFS('MAINTENANCE LOG'!$O$8:$O$107,'MAINTENANCE LOG'!$C$8:$C$107,$B19)) -> 0 | H19: =IF($B19="","",$E19-$G19) -> 0 | I19: =IF($B19="","",COUNTIFS('MAINTENANCE LOG'!$C$8:$C$107,$B19,'MAINTENANCE LOG'!$AA$8:$AA$107,"REPEAT")) -> 0
B20: ='EQUIPMENT REGISTER'!$B$12 -> RCPM008 | C20: ='EQUIPMENT REGISTER'!$C$12 -> Grader | D20: =IF($B20="","",COUNTIFS('MAINTENANCE LOG'!$C$8:$C$107,$B20,'MAINTENANCE LOG'!$Z$8:$Z$107,"Completed")) -> 0 | E20: =IF($B20="","",SUMIFS('MAINTENANCE LOG'!$R$8:$R$107,'MAINTENANCE LOG'!$C$8:$C$107,$B20,'MAINTENANCE LOG'!$Z$8:$Z$107,"Completed")) -> 0 | F20: =IF($B20="","",IFERROR($E20/$D20,0)) -> 0 | G20: =IF($B20="","",SUMIFS('MAINTENANCE LOG'!$O$8:$O$107,'MAINTENANCE LOG'!$C$8:$C$107,$B20)) -> 0 | H20: =IF($B20="","",$E20-$G20) -> 0 | I20: =IF($B20="","",COUNTIFS('MAINTENANCE LOG'!$C$8:$C$107,$B20,'MAINTENANCE LOG'!$AA$8:$AA$107,"REPEAT")) -> 0
B21: ='EQUIPMENT REGISTER'!$B$13 -> RCPM009 | C21: ='EQUIPMENT REGISTER'!$C$13 -> Compactor | D21: =IF($B21="","",COUNTIFS('MAINTENANCE LOG'!$C$8:$C$107,$B21,'MAINTENANCE LOG'!$Z$8:$Z$107,"Completed")) -> 0 | E21: =IF($B21="","",SUMIFS('MAINTENANCE LOG'!$R$8:$R$107,'MAINTENANCE LOG'!$C$8:$C$107,$B21,'MAINTENANCE LOG'!$Z$8:$Z$107,"Completed")) -> 0 | F21: =IF($B21="","",IFERROR($E21/$D21,0)) -> 0 | G21: =IF($B21="","",SUMIFS('MAINTENANCE LOG'!$O$8:$O$107,'MAINTENANCE LOG'!$C$8:$C$107,$B21)) -> 0 | H21: =IF($B21="","",$E21-$G21) -> 0 | I21: =IF($B21="","",COUNTIFS('MAINTENANCE LOG'!$C$8:$C$107,$B21,'MAINTENANCE LOG'!$AA$8:$AA$107,"REPEAT")) -> 0
B22: ='EQUIPMENT REGISTER'!$B$14 -> RCPM010 | C22: ='EQUIPMENT REGISTER'!$C$14 -> TLB | D22: =IF($B22="","",COUNTIFS('MAINTENANCE LOG'!$C$8:$C$107,$B22,'MAINTENANCE LOG'!$Z$8:$Z$107,"Completed")) -> 0 | E22: =IF($B22="","",SUMIFS('MAINTENANCE LOG'!$R$8:$R$107,'MAINTENANCE LOG'!$C$8:$C$107,$B22,'MAINTENANCE LOG'!$Z$8:$Z$107,"Completed")) -> 0 | F22: =IF($B22="","",IFERROR($E22/$D22,0)) -> 0 | G22: =IF($B22="","",SUMIFS('MAINTENANCE LOG'!$O$8:$O$107,'MAINTENANCE LOG'!$C$8:$C$107,$B22)) -> 0 | H22: =IF($B22="","",$E22-$G22) -> 0 | I22: =IF($B22="","",COUNTIFS('MAINTENANCE LOG'!$C$8:$C$107,$B22,'MAINTENANCE LOG'!$AA$8:$AA$107,"REPEAT")) -> 0
B23: ='EQUIPMENT REGISTER'!$B$15 -> RCPM023 | C23: ='EQUIPMENT REGISTER'!$C$15 -> Water Bowser | D23: =IF($B23="","",COUNTIFS('MAINTENANCE LOG'!$C$8:$C$107,$B23,'MAINTENANCE LOG'!$Z$8:$Z$107,"Completed")) -> 0 | E23: =IF($B23="","",SUMIFS('MAINTENANCE LOG'!$R$8:$R$107,'MAINTENANCE LOG'!$C$8:$C$107,$B23,'MAINTENANCE LOG'!$Z$8:$Z$107,"Completed")) -> 0 | F23: =IF($B23="","",IFERROR($E23/$D23,0)) -> 0 | G23: =IF($B23="","",SUMIFS('MAINTENANCE LOG'!$O$8:$O$107,'MAINTENANCE LOG'!$C$8:$C$107,$B23)) -> 0 | H23: =IF($B23="","",$E23-$G23) -> 0 | I23: =IF($B23="","",COUNTIFS('MAINTENANCE LOG'!$C$8:$C$107,$B23,'MAINTENANCE LOG'!$AA$8:$AA$107,"REPEAT")) -> 0
B24: ='EQUIPMENT REGISTER'!$B$16 -> RCPM024 | C24: ='EQUIPMENT REGISTER'!$C$16 -> Water Bowser | D24: =IF($B24="","",COUNTIFS('MAINTENANCE LOG'!$C$8:$C$107,$B24,'MAINTENANCE LOG'!$Z$8:$Z$107,"Completed")) -> 0 | E24: =IF($B24="","",SUMIFS('MAINTENANCE LOG'!$R$8:$R$107,'MAINTENANCE LOG'!$C$8:$C$107,$B24,'MAINTENANCE LOG'!$Z$8:$Z$107,"Completed")) -> 0 | F24: =IF($B24="","",IFERROR($E24/$D24,0)) -> 0 | G24: =IF($B24="","",SUMIFS('MAINTENANCE LOG'!$O$8:$O$107,'MAINTENANCE LOG'!$C$8:$C$107,$B24)) -> 0 | H24: =IF($B24="","",$E24-$G24) -> 0 | I24: =IF($B24="","",COUNTIFS('MAINTENANCE LOG'!$C$8:$C$107,$B24,'MAINTENANCE LOG'!$AA$8:$AA$107,"REPEAT")) -> 0
B25: ='EQUIPMENT REGISTER'!$B$17 -> 0 | C25: ='EQUIPMENT REGISTER'!$C$17 -> 0 | D25: =IF($B25="","",COUNTIFS('MAINTENANCE LOG'!$C$8:$C$107,$B25,'MAINTENANCE LOG'!$Z$8:$Z$107,"Completed")) -> 0 | E25: =IF($B25="","",SUMIFS('MAINTENANCE LOG'!$R$8:$R$107,'MAINTENANCE LOG'!$C$8:$C$107,$B25,'MAINTENANCE LOG'!$Z$8:$Z$107,"Completed")) -> 0 | F25: =IF($B25="","",IFERROR($E25/$D25,0)) -> 0 | G25: =IF($B25="","",SUMIFS('MAINTENANCE LOG'!$O$8:$O$107,'MAINTENANCE LOG'!$C$8:$C$107,$B25)) -> 0 | H25: =IF($B25="","",$E25-$G25) -> 0 | I25: =IF($B25="","",COUNTIFS('MAINTENANCE LOG'!$C$8:$C$107,$B25,'MAINTENANCE LOG'!$AA$8:$AA$107,"REPEAT")) -> 0
B26: ='EQUIPMENT REGISTER'!$B$18 -> 0 | C26: ='EQUIPMENT REGISTER'!$C$18 -> 0 | D26: =IF($B26="","",COUNTIFS('MAINTENANCE LOG'!$C$8:$C$107,$B26,'MAINTENANCE LOG'!$Z$8:$Z$107,"Completed")) -> 0 | E26: =IF($B26="","",SUMIFS('MAINTENANCE LOG'!$R$8:$R$107,'MAINTENANCE LOG'!$C$8:$C$107,$B26,'MAINTENANCE LOG'!$Z$8:$Z$107,"Completed")) -> 0 | F26: =IF($B26="","",IFERROR($E26/$D26,0)) -> 0 | G26: =IF($B26="","",SUMIFS('MAINTENANCE LOG'!$O$8:$O$107,'MAINTENANCE LOG'!$C$8:$C$107,$B26)) -> 0 | H26: =IF($B26="","",$E26-$G26) -> 0 | I26: =IF($B26="","",COUNTIFS('MAINTENANCE LOG'!$C$8:$C$107,$B26,'MAINTENANCE LOG'!$AA$8:$AA$107,"REPEAT")) -> 0
B27: ='EQUIPMENT REGISTER'!$B$19 -> 0 | C27: ='EQUIPMENT REGISTER'!$C$19 -> 0 | D27: =IF($B27="","",COUNTIFS('MAINTENANCE LOG'!$C$8:$C$107,$B27,'MAINTENANCE LOG'!$Z$8:$Z$107,"Completed")) -> 0 | E27: =IF($B27="","",SUMIFS('MAINTENANCE LOG'!$R$8:$R$107,'MAINTENANCE LOG'!$C$8:$C$107,$B27,'MAINTENANCE LOG'!$Z$8:$Z$107,"Completed")) -> 0 | F27: =IF($B27="","",IFERROR($E27/$D27,0)) -> 0 | G27: =IF($B27="","",SUMIFS('MAINTENANCE LOG'!$O$8:$O$107,'MAINTENANCE LOG'!$C$8:$C$107,$B27)) -> 0 | H27: =IF($B27="","",$E27-$G27) -> 0 | I27: =IF($B27="","",COUNTIFS('MAINTENANCE LOG'!$C$8:$C$107,$B27,'MAINTENANCE LOG'!$AA$8:$AA$107,"REPEAT")) -> 0
B28: ='EQUIPMENT REGISTER'!$B$20 -> 0 | C28: ='EQUIPMENT REGISTER'!$C$20 -> 0 | D28: =IF($B28="","",COUNTIFS('MAINTENANCE LOG'!$C$8:$C$107,$B28,'MAINTENANCE LOG'!$Z$8:$Z$107,"Completed")) -> 0 | E28: =IF($B28="","",SUMIFS('MAINTENANCE LOG'!$R$8:$R$107,'MAINTENANCE LOG'!$C$8:$C$107,$B28,'MAINTENANCE LOG'!$Z$8:$Z$107,"Completed")) -> 0 | F28: =IF($B28="","",IFERROR($E28/$D28,0)) -> 0 | G28: =IF($B28="","",SUMIFS('MAINTENANCE LOG'!$O$8:$O$107,'MAINTENANCE LOG'!$C$8:$C$107,$B28)) -> 0 | H28: =IF($B28="","",$E28-$G28) -> 0 | I28: =IF($B28="","",COUNTIFS('MAINTENANCE LOG'!$C$8:$C$107,$B28,'MAINTENANCE LOG'!$AA$8:$AA$107,"REPEAT")) -> 0
B29: ='EQUIPMENT REGISTER'!$B$21 -> 0 | C29: ='EQUIPMENT REGISTER'!$C$21 -> 0 | D29: =IF($B29="","",COUNTIFS('MAINTENANCE LOG'!$C$8:$C$107,$B29,'MAINTENANCE LOG'!$Z$8:$Z$107,"Completed")) -> 0 | E29: =IF($B29="","",SUMIFS('MAINTENANCE LOG'!$R$8:$R$107,'MAINTENANCE LOG'!$C$8:$C$107,$B29,'MAINTENANCE LOG'!$Z$8:$Z$107,"Completed")) -> 0 | F29: =IF($B29="","",IFERROR($E29/$D29,0)) -> 0 | G29: =IF($B29="","",SUMIFS('MAINTENANCE LOG'!$O$8:$O$107,'MAINTENANCE LOG'!$C$8:$C$107,$B29)) -> 0 | H29: =IF($B29="","",$E29-$G29) -> 0 | I29: =IF($B29="","",COUNTIFS('MAINTENANCE LOG'!$C$8:$C$107,$B29,'MAINTENANCE LOG'!$AA$8:$AA$107,"REPEAT")) -> 0
B31: MTTR BY BREAKDOWN TYPE
B32: CATEGORY | C32: JOBS | D32: COMPLETED | E32: TOTAL REPAIR HRS | F32: MTTR (HRS) | G32: REPEAT B/DOWNS
B33: Engine | C33: =COUNTIF('MAINTENANCE LOG'!$F$8:$F$107,$B33) -> 0 | D33: =COUNTIFS('MAINTENANCE LOG'!$F$8:$F$107,$B33,'MAINTENANCE LOG'!$Z$8:$Z$107,"Completed") -> 0 | E33: =SUMIFS('MAINTENANCE LOG'!$R$8:$R$107,'MAINTENANCE LOG'!$F$8:$F$107,$B33,'MAINTENANCE LOG'!$Z$8:$Z$107,"Completed") -> 0 | F33: =IFERROR($E33/$D33,0) -> 0 | G33: =COUNTIFS('MAINTENANCE LOG'!$F$8:$F$107,$B33,'MAINTENANCE LOG'!$AA$8:$AA$107,"REPEAT") -> 0
B34: Hydraulic | C34: =COUNTIF('MAINTENANCE LOG'!$F$8:$F$107,$B34) -> 0 | D34: =COUNTIFS('MAINTENANCE LOG'!$F$8:$F$107,$B34,'MAINTENANCE LOG'!$Z$8:$Z$107,"Completed") -> 0 | E34: =SUMIFS('MAINTENANCE LOG'!$R$8:$R$107,'MAINTENANCE LOG'!$F$8:$F$107,$B34,'MAINTENANCE LOG'!$Z$8:$Z$107,"Completed") -> 0 | F34: =IFERROR($E34/$D34,0) -> 0 | G34: =COUNTIFS('MAINTENANCE LOG'!$F$8:$F$107,$B34,'MAINTENANCE LOG'!$AA$8:$AA$107,"REPEAT") -> 0
B35: Electrical | C35: =COUNTIF('MAINTENANCE LOG'!$F$8:$F$107,$B35) -> 0 | D35: =COUNTIFS('MAINTENANCE LOG'!$F$8:$F$107,$B35,'MAINTENANCE LOG'!$Z$8:$Z$107,"Completed") -> 0 | E35: =SUMIFS('MAINTENANCE LOG'!$R$8:$R$107,'MAINTENANCE LOG'!$F$8:$F$107,$B35,'MAINTENANCE LOG'!$Z$8:$Z$107,"Completed") -> 0 | F35: =IFERROR($E35/$D35,0) -> 0 | G35: =COUNTIFS('MAINTENANCE LOG'!$F$8:$F$107,$B35,'MAINTENANCE LOG'!$AA$8:$AA$107,"REPEAT") -> 0
B36: Transmission | C36: =COUNTIF('MAINTENANCE LOG'!$F$8:$F$107,$B36) -> 0 | D36: =COUNTIFS('MAINTENANCE LOG'!$F$8:$F$107,$B36,'MAINTENANCE LOG'!$Z$8:$Z$107,"Completed") -> 0 | E36: =SUMIFS('MAINTENANCE LOG'!$R$8:$R$107,'MAINTENANCE LOG'!$F$8:$F$107,$B36,'MAINTENANCE LOG'!$Z$8:$Z$107,"Completed") -> 0 | F36: =IFERROR($E36/$D36,0) -> 0 | G36: =COUNTIFS('MAINTENANCE LOG'!$F$8:$F$107,$B36,'MAINTENANCE LOG'!$AA$8:$AA$107,"REPEAT") -> 0
B37: Undercarriage | C37: =COUNTIF('MAINTENANCE LOG'!$F$8:$F$107,$B37) -> 0 | D37: =COUNTIFS('MAINTENANCE LOG'!$F$8:$F$107,$B37,'MAINTENANCE LOG'!$Z$8:$Z$107,"Completed") -> 0 | E37: =SUMIFS('MAINTENANCE LOG'!$R$8:$R$107,'MAINTENANCE LOG'!$F$8:$F$107,$B37,'MAINTENANCE LOG'!$Z$8:$Z$107,"Completed") -> 0 | F37: =IFERROR($E37/$D37,0) -> 0 | G37: =COUNTIFS('MAINTENANCE LOG'!$F$8:$F$107,$B37,'MAINTENANCE LOG'!$AA$8:$AA$107,"REPEAT") -> 0
B38: Tyres | C38: =COUNTIF('MAINTENANCE LOG'!$F$8:$F$107,$B38) -> 1 | D38: =COUNTIFS('MAINTENANCE LOG'!$F$8:$F$107,$B38,'MAINTENANCE LOG'!$Z$8:$Z$107,"Completed") -> 0 | E38: =SUMIFS('MAINTENANCE LOG'!$R$8:$R$107,'MAINTENANCE LOG'!$F$8:$F$107,$B38,'MAINTENANCE LOG'!$Z$8:$Z$107,"Completed") -> 0 | F38: =IFERROR($E38/$D38,0) -> 0 | G38: =COUNTIFS('MAINTENANCE LOG'!$F$8:$F$107,$B38,'MAINTENANCE LOG'!$AA$8:$AA$107,"REPEAT") -> 0
B39: Brakes | C39: =COUNTIF('MAINTENANCE LOG'!$F$8:$F$107,$B39) -> 0 | D39: =COUNTIFS('MAINTENANCE LOG'!$F$8:$F$107,$B39,'MAINTENANCE LOG'!$Z$8:$Z$107,"Completed") -> 0 | E39: =SUMIFS('MAINTENANCE LOG'!$R$8:$R$107,'MAINTENANCE LOG'!$F$8:$F$107,$B39,'MAINTENANCE LOG'!$Z$8:$Z$107,"Completed") -> 0 | F39: =IFERROR($E39/$D39,0) -> 0 | G39: =COUNTIFS('MAINTENANCE LOG'!$F$8:$F$107,$B39,'MAINTENANCE LOG'!$AA$8:$AA$107,"REPEAT") -> 0
B40: Cooling | C40: =COUNTIF('MAINTENANCE LOG'!$F$8:$F$107,$B40) -> 0 | D40: =COUNTIFS('MAINTENANCE LOG'!$F$8:$F$107,$B40,'MAINTENANCE LOG'!$Z$8:$Z$107,"Completed") -> 0 | E40: =SUMIFS('MAINTENANCE LOG'!$R$8:$R$107,'MAINTENANCE LOG'!$F$8:$F$107,$B40,'MAINTENANCE LOG'!$Z$8:$Z$107,"Completed") -> 0 | F40: =IFERROR($E40/$D40,0) -> 0 | G40: =COUNTIFS('MAINTENANCE LOG'!$F$8:$F$107,$B40,'MAINTENANCE LOG'!$AA$8:$AA$107,"REPEAT") -> 0
B41: Body & Structure | C41: =COUNTIF('MAINTENANCE LOG'!$F$8:$F$107,$B41) -> 0 | D41: =COUNTIFS('MAINTENANCE LOG'!$F$8:$F$107,$B41,'MAINTENANCE LOG'!$Z$8:$Z$107,"Completed") -> 0 | E41: =SUMIFS('MAINTENANCE LOG'!$R$8:$R$107,'MAINTENANCE LOG'!$F$8:$F$107,$B41,'MAINTENANCE LOG'!$Z$8:$Z$107,"Completed") -> 0 | F41: =IFERROR($E41/$D41,0) -> 0 | G41: =COUNTIFS('MAINTENANCE LOG'!$F$8:$F$107,$B41,'MAINTENANCE LOG'!$AA$8:$AA$107,"REPEAT") -> 0
B42: Operator Damage | C42: =COUNTIF('MAINTENANCE LOG'!$F$8:$F$107,$B42) -> 0 | D42: =COUNTIFS('MAINTENANCE LOG'!$F$8:$F$107,$B42,'MAINTENANCE LOG'!$Z$8:$Z$107,"Completed") -> 0 | E42: =SUMIFS('MAINTENANCE LOG'!$R$8:$R$107,'MAINTENANCE LOG'!$F$8:$F$107,$B42,'MAINTENANCE LOG'!$Z$8:$Z$107,"Completed") -> 0 | F42: =IFERROR($E42/$D42,0) -> 0 | G42: =COUNTIFS('MAINTENANCE LOG'!$F$8:$F$107,$B42,'MAINTENANCE LOG'!$AA$8:$AA$107,"REPEAT") -> 0
B43: Other | C43: =COUNTIF('MAINTENANCE LOG'!$F$8:$F$107,$B43) -> 0 | D43: =COUNTIFS('MAINTENANCE LOG'!$F$8:$F$107,$B43,'MAINTENANCE LOG'!$Z$8:$Z$107,"Completed") -> 0 | E43: =SUMIFS('MAINTENANCE LOG'!$R$8:$R$107,'MAINTENANCE LOG'!$F$8:$F$107,$B43,'MAINTENANCE LOG'!$Z$8:$Z$107,"Completed") -> 0 | F43: =IFERROR($E43/$D43,0) -> 0 | G43: =COUNTIFS('MAINTENANCE LOG'!$F$8:$F$107,$B43,'MAINTENANCE LOG'!$AA$8:$AA$107,"REPEAT") -> 0
B46: MTTR BY SHIFT
...

Sheet AVAILABILITY
B2: ENGINEERING AVAILABILITY
B3: Exxaro Grootegeluk | PLANT OPTIMIZATION
B4: Availability is an engineering KPI and is measured separately from production utilisation.
B6: EQUIP | C6: MACHINE TYPE | D6: PLANNED AVAIL HRS | E6: BREAKDOWN HRS | F6: TARGET AVAIL | G6: ACTUAL AVAIL | H6: VARIANCE
B7: CRT220 | C7: CAT 773 RDT | D7: ='SETUP & TARGETS'!$C$10*COUNT('CRT220'!$O$7:$O$37) -> 270 | E7: ='CRT220'!I38 -> 270 | F7: ='SETUP & TARGETS'!$C12 -> 0.85 | G7: =IFERROR((D7-E7)/D7,0) -> 0 | H7: =G7-F7 -> -0.85
B8: CRT221 | C8: CAT 773 RDT | D8: ='SETUP & TARGETS'!$C$10*COUNT('CRT221'!$O$7:$O$37) -> 270 | E8: ='CRT221'!I38 -> 77 | F8: ='SETUP & TARGETS'!$C12 -> 0.85 | G8: =IFERROR((D8-E8)/D8,0) -> 0.71481481 | H8: =G8-F8 -> -0.13518519
B9: CRT222 | C9: CAT 773 RDT | D9: ='SETUP & TARGETS'!$C$10*COUNT('CRT222'!$O$7:$O$37) -> 270 | E9: ='CRT222'!I38 -> 145 | F9: ='SETUP & TARGETS'!$C12 -> 0.85 | G9: =IFERROR((D9-E9)/D9,0) -> 0.46296296 | H9: =G9-F9 -> -0.38703704
B10: CRT224 | C10: CAT 395 Excavator | D10: ='SETUP & TARGETS'!$C$10*COUNT('CRT224'!$O$7:$O$37) -> 270 | E10: ='CRT224'!I38 -> 11 | F10: ='SETUP & TARGETS'!$C12 -> 0.85 | G10: =IFERROR((D10-E10)/D10,0) -> 0.95925926 | H10: =G10-F10 -> 0.10925926
B11: CRT225 | C11: CAT D9 Dozer | D11: ='SETUP & TARGETS'!$C$10*COUNT('CRT225'!$O$7:$O$37) -> 270 | E11: ='CRT225'!I38 -> 0 | F11: ='SETUP & TARGETS'!$C12 -> 0.85 | G11: =IFERROR((D11-E11)/D11,0) -> 1 | H11: =G11-F11 -> 0.15
B12: FLEET | D12: =SUM(D7:D11) -> 1350 | E12: =SUM(E7:E11) -> 503 | F12: ='SETUP & TARGETS'!$C12 -> 0.85 | G12: =IFERROR((D12-E12)/D12,0) -> 0.62740741 | H12: =G12-F12 -> -0.22259259
B14: RENTAL & STANDBY FLEET - AVAILABILITY AND UTILISATION
B15: For machines without a daily machine tab. Breakdown and planned maintenance hours come from the MAINTENANCE LOG, so the reason for every unavailable hour is traceable.
B16: EQUIP | C16: EQUIPMENT TYPE | D16: STATUS | E16: PLANNED HRS | F16: B/DOWN HRS | G16: PLANNED MAINT HRS | H16: OTHER DOWNTIME | I16: AVAILABLE HRS | J16: AVAILABILITY % | K16: OPERATING HRS | L16: IDLE HRS | M16: UTILISATION % | N16: RAG
B17: ='EQUIPMENT REGISTER'!$B$12 -> RCPM008 | C17: ='EQUIPMENT REGISTER'!$C$12 -> Grader | D17: ='EQUIPMENT REGISTER'!$F$12 -> Active | F17: =SUMIFS('MAINTENANCE LOG'!$R$8:$R$107,'MAINTENANCE LOG'!$C$8:$C$107,$B17,'MAINTENANCE LOG'!$E$8:$E$107,"Breakdown") -> 0 | G17: =SUMIFS('MAINTENANCE LOG'!$R$8:$R$107,'MAINTENANCE LOG'!$C$8:$C$107,$B17,'MAINTENANCE LOG'!$E$8:$E$107,"Planned Maintenance")+SUMIFS('MAINTENANCE LOG'!$R$8:$R$107,'MAINTENANCE LOG'!$C$8:$C$107,$B17,'MAINTENANCE LOG'!$E$8:$E$107,"Service") -> 0 | I17: =MAX(0,N($E17)-N($F17)-N($G17)-N($H17)) -> 0 | J17: =IFERROR($I17/$E17,0) -> 0 | L17: =MAX(0,N($I17)-N($K17)) -> 0 | M17: =IFERROR($K17/$I17,0) -> 0 | N17: =IF(N($E17)=0,"",IF($J17>='SETUP & TARGETS'!$C$12,"GREEN",IF($J17>='SETUP & TARGETS'!$C$13,"AMBER","RED")))
B18: ='EQUIPMENT REGISTER'!$B$13 -> RCPM009 | C18: ='EQUIPMENT REGISTER'!$C$13 -> Compactor | D18: ='EQUIPMENT REGISTER'!$F$13 -> Active | F18: =SUMIFS('MAINTENANCE LOG'!$R$8:$R$107,'MAINTENANCE LOG'!$C$8:$C$107,$B18,'MAINTENANCE LOG'!$E$8:$E$107,"Breakdown") -> 0 | G18: =SUMIFS('MAINTENANCE LOG'!$R$8:$R$107,'MAINTENANCE LOG'!$C$8:$C$107,$B18,'MAINTENANCE LOG'!$E$8:$E$107,"Planned Maintenance")+SUMIFS('MAINTENANCE LOG'!$R$8:$R$107,'MAINTENANCE LOG'!$C$8:$C$107,$B18,'MAINTENANCE LOG'!$E$8:$E$107,"Service") -> 0 | I18: =MAX(0,N($E18)-N($F18)-N($G18)-N($H18)) -> 0 | J18: =IFERROR($I18/$E18,0) -> 0 | L18: =MAX(0,N($I18)-N($K18)) -> 0 | M18: =IFERROR($K18/$I18,0) -> 0 | N18: =IF(N($E18)=0,"",IF($J18>='SETUP & TARGETS'!$C$12,"GREEN",IF($J18>='SETUP & TARGETS'!$C$13,"AMBER","RED")))
B19: ='EQUIPMENT REGISTER'!$B$14 -> RCPM010 | C19: ='EQUIPMENT REGISTER'!$C$14 -> TLB | D19: ='EQUIPMENT REGISTER'!$F$14 -> Inactive | F19: =SUMIFS('MAINTENANCE LOG'!$R$8:$R$107,'MAINTENANCE LOG'!$C$8:$C$107,$B19,'MAINTENANCE LOG'!$E$8:$E$107,"Breakdown") -> 0 | G19: =SUMIFS('MAINTENANCE LOG'!$R$8:$R$107,'MAINTENANCE LOG'!$C$8:$C$107,$B19,'MAINTENANCE LOG'!$E$8:$E$107,"Planned Maintenance")+SUMIFS('MAINTENANCE LOG'!$R$8:$R$107,'MAINTENANCE LOG'!$C$8:$C$107,$B19,'MAINTENANCE LOG'!$E$8:$E$107,"Service") -> 0 | I19: =MAX(0,N($E19)-N($F19)-N($G19)-N($H19)) -> 0 | J19: =IFERROR($I19/$E19,0) -> 0 | L19: =MAX(0,N($I19)-N($K19)) -> 0 | M19: =IFERROR($K19/$I19,0) -> 0 | N19: =IF(N($E19)=0,"",IF($J19>='SETUP & TARGETS'!$C$12,"GREEN",IF($J19>='SETUP & TARGETS'!$C$13,"AMBER","RED")))
B20: ='EQUIPMENT REGISTER'!$B$15 -> RCPM023 | C20: ='EQUIPMENT REGISTER'!$C$15 -> Water Bowser | D20: ='EQUIPMENT REGISTER'!$F$15 -> Active | F20: =SUMIFS('MAINTENANCE LOG'!$R$8:$R$107,'MAINTENANCE LOG'!$C$8:$C$107,$B20,'MAINTENANCE LOG'!$E$8:$E$107,"Breakdown") -> 0 | G20: =SUMIFS('MAINTENANCE LOG'!$R$8:$R$107,'MAINTENANCE LOG'!$C$8:$C$107,$B20,'MAINTENANCE LOG'!$E$8:$E$107,"Planned Maintenance")+SUMIFS('MAINTENANCE LOG'!$R$8:$R$107,'MAINTENANCE LOG'!$C$8:$C$107,$B20,'MAINTENANCE LOG'!$E$8:$E$107,"Service") -> 0 | I20: =MAX(0,N($E20)-N($F20)-N($G20)-N($H20)) -> 0 | J20: =IFERROR($I20/$E20,0) -> 0 | L20: =MAX(0,N($I20)-N($K20)) -> 0 | M20: =IFERROR($K20/$I20,0) -> 0 | N20: =IF(N($E20)=0,"",IF($J20>='SETUP & TARGETS'!$C$12,"GREEN",IF($J20>='SETUP & TARGETS'!$C$13,"AMBER","RED")))
B21: ='EQUIPMENT REGISTER'!$B$16 -> RCPM024 | C21: ='EQUIPMENT REGISTER'!$C$16 -> Water Bowser | D21: ='EQUIPMENT REGISTER'!$F$16 -> Inactive | F21: =SUMIFS('MAINTENANCE LOG'!$R$8:$R$107,'MAINTENANCE LOG'!$C$8:$C$107,$B21,'MAINTENANCE LOG'!$E$8:$E$107,"Breakdown") -> 0 | G21: =SUMIFS('MAINTENANCE LOG'!$R$8:$R$107,'MAINTENANCE LOG'!$C$8:$C$107,$B21,'MAINTENANCE LOG'!$E$8:$E$107,"Planned Maintenance")+SUMIFS('MAINTENANCE LOG'!$R$8:$R$107,'MAINTENANCE LOG'!$C$8:$C$107,$B21,'MAINTENANCE LOG'!$E$8:$E$107,"Service") -> 0 | I21: =MAX(0,N($E21)-N($F21)-N($G21)-N($H21)) -> 0 | J21: =IFERROR($I21/$E21,0) -> 0 | L21: =MAX(0,N($I21)-N($K21)) -> 0 | M21: =IFERROR($K21/$I21,0) -> 0 | N21: =IF(N($E21)=0,"",IF($J21>='SETUP & TARGETS'!$C$12,"GREEN",IF($J21>='SETUP & TARGETS'!$C$13,"AMBER","RED")))
B22: RENTAL TOTAL | E22: =SUM(E17:E21) -> 0 | F22: =SUM(F17:F21) -> 0 | G22: =SUM(G17:G21) -> 0 | H22: =SUM(H17:H21) -> 0 | I22: =SUM(I17:I21) -> 0 | J22: =IFERROR($I22/$E22,0) -> 0 | K22: =SUM(K17:K21) -> 0 | L22: =SUM(L17:L21) -> 0 | M22: =IFERROR($K22/$I22,0) -> 0
B24: Planned hours, other downtime and operating hours are captured per contract. Availability = available hours / planned hours. Utilisation = operating hours / available hours. The two are deliberately kept separate.

Sheet SETUP & TARGETS
B2: SETUP & TARGETS
B3: Exxaro Grootegeluk | APRIL 2026 | PLANT OPTIMIZATION
B4: Blue cells are inputs. Change them here and the whole workbook follows.
B6: OPERATING PARAMETERS
B7: Shift hours per day | C7: 18 | E7: Targeted hours on the machine per working day
B8: Working days per month | C8: 31 | E8: Monday to Friday basis
B9: Planned operating hours per month | C9: =C7*C8 -> 558 | E9: Shift hours x working days - calculated
B10: Planned available hours per day | C10: 18 | E10: Engineering availability window per day
B11: Utilisation target | C11: 0.8 | E11: Green at or above this share of the cumulative target
B12: Availability target | C12: 0.85 | E12: Allows for daily inspections, breakdowns and scheduled maintenance
B13: Amber threshold | C13: 0.7 | E13: Below the utilisation target but above this is amber
B14: Calendar days in month | C14: 31 | E14: Number of day rows on each machine tab
B17: FLEET REGISTER
B18: EQUIP CODE | C18: MACHINE TYPE | D18: PLANNED HRS | E18: STATUS
B19: CRT220 | C19: CAT 773 RDT | D19: ='SETUP & TARGETS'!$C9 -> 558 | E19: ACTIVE
B20: CRT221 | C20: CAT 773 RDT | D20: ='SETUP & TARGETS'!$C9 -> 558 | E20: ACTIVE
B21: CRT222 | C21: CAT 773 RDT | D21: ='SETUP & TARGETS'!$C9 -> 558 | E21: ACTIVE
B22: CRT224 | C22: CAT 395 Excavator | D22: ='SETUP & TARGETS'!$C9 -> 558 | E22: ACTIVE
B23: CRT225 | C23: CAT D9 Dozer | D23: ='SETUP & TARGETS'!$C9 -> 558 | E23: ACTIVE
B25: Planned operating hours = shift hours x working days. Confirm the GGV shift pattern with the Site Manager.
B27: MECHANICAL TEAM PARAMETERS
B28: Mechanical shift length (hours) | C28: 12 | E28: Day shift 06:00 to 18:00, night shift 18:00 to 06:00
B29: Labour utilisation target | C29: 0.8 | E29: Productive mechanical hours as a share of hours on site
B30: ETR compliance target | C30: 0.9 | E30: Share of repairs completed by the estimated time of repair
B31: MTTR baseline (hours) | E31: Left blank on purpose - no external benchmark assumed. Populate once GG has run enough months to set its own baseline
B32: Service interval (engine hours) | C32: 250 | E32: Used for guidance only - next service date is captured per machine
B33: Inspection interval (days) | C33: 7 | E33: Drives the next inspection date on the EQUIPMENT REGISTER
B34: Service / inspection warning (days) | C34: 7 | E34: Days before due date that a machine flags as DUE
B35: Maintenance backlog - amber (open jobs) | C35: 3 | E35: Open or in-progress jobs per machine before it flags amber
B36: Maintenance backlog - red (open jobs) | C36: 6 | E36: Open or in-progress jobs per machine before it flags red
B38: MECHANICAL TEAM REGISTER
B39: NAME | C39: POSITION | D39: ROSTER PATTERN | E39: SHIFT HRS
B40: Lindokuhle Ntombela | C40: Mechanic / Acting Team Leader | D40: Monday to Friday - Day | E40: =$C$28 -> 12
B41: Motlalepula Molefe | C41: Mechanic | D41: Cycle group A - 3 day / 3 night / 3 off | E41: =$C$28 -> 12
B42: Thabo Monyane | C42: Mechanic | D42: Cycle group B - 3 day / 3 night / 3 off | E42: =$C$28 -> 12
B43: Tshepang Maepa | C43: Assistant Mechanic | D43: Cycle group C - 3 day / 3 night / 3 off | E43: =$C$28 -> 12
B45: Names come from the GGV Lephalale shift roster. Change a name here and the roster, maintenance log and mechanic performance tabs all follow.

Sheet CRT220
B2: EQUIPMENT LOG | CRT220 - CAT 773 RDT
B3: Exxaro Grootegeluk | PLANT OPTIMIZATION
B6: DATE | C6: WORK DAY | D6: OPENING ENG HRS | E6: CLOSING ENG HRS | F6: DIRECT OPS HRS | G6: DELAY CODE(S) | H6: OPS DELAY HRS | I6: B/DOWN HRS | J6: DAILY TARGET | K6: CUM TARGET | L6: CUM ACTUAL | M6: CUM ACHIEVED | N6: DAILY UTIL % | O6: DAILY AVAIL % | P6: RAG | Q6: COMMENTS / DETAILS
B7: 46266 | C7: Y | D7: 10165 | E7: 10165 | F7: =IF(OR($E7="",$D7=""),"",MAX(0,$E7-$D7)) -> 0 | G7: BD-CC | I7: 18 | J7: =IF($C7="Y",'SETUP & TARGETS'!$C$7,0) -> 18 | K7: =0+$J7 -> 18 | L7: =0+N($F7) -> 0 | M7: =IFERROR($L7/$K7,0) -> 0 | N7: =IF($F7="","",IFERROR($F7/'SETUP & TARGETS'!$C7,0)) -> 0 | O7: =IF(OR($C7<>"Y",COUNT($D7,$E7,$H7,$I7)=0),"",MAX(0,IFERROR(('SETUP & TARGETS'!$C$10-N($I7))/'SETUP & TARGETS'!$C$10,0))) -> 0 | P7: =IF($K7=0,"",IF($M7>='SETUP & TARGETS'!$C11,"GREEN",IF($M7>='SETUP & TARGETS'!$C13,"AMBER","RED"))) -> RED | Q7: =IFERROR(INDEX('DELAY CODE REGISTER'!$C$6:$C$49,MATCH(G7,'DELAY CODE REGISTER'!$B$6:$B$49,0)),"") -> Breakdown:Component change out
B8: 46267 | C8: Y | D8: 10165 | E8: 10165 | F8: =IF(OR($E8="",$D8=""),"",MAX(0,$E8-$D8)) -> 0 | G8: BD-CC | I8: 18 | J8: =IF($C8="Y",'SETUP & TARGETS'!$C$7,0) -> 18 | K8: =$K7+$J8 -> 36 | L8: =$L7+N($F8) -> 0 | M8: =IFERROR($L8/$K8,0) -> 0 | N8: =IF($F8="","",IFERROR($F8/'SETUP & TARGETS'!$C7,0)) -> 0 | O8: =IF(OR($C8<>"Y",COUNT($D8,$E8,$H8,$I8)=0),"",MAX(0,IFERROR(('SETUP & TARGETS'!$C$10-N($I8))/'SETUP & TARGETS'!$C$10,0))) -> 0 | P8: =IF($K8=0,"",IF($M8>='SETUP & TARGETS'!$C11,"GREEN",IF($M8>='SETUP & TARGETS'!$C13,"AMBER","RED"))) -> RED | Q8: =IFERROR(INDEX('DELAY CODE REGISTER'!$C$6:$C$49,MATCH(G8,'DELAY CODE REGISTER'!$B$6:$B$49,0)),"") -> Breakdown:Component change out
B9: 46268 | C9: Y | D9: 10165 | E9: 10165 | F9: =IF(OR($E9="",$D9=""),"",MAX(0,$E9-$D9)) -> 0 | G9: BD-CC | I9: 18 | J9: =IF($C9="Y",'SETUP & TARGETS'!$C$7,0) -> 18 | K9: =$K8+$J9 -> 54 | L9: =$L8+N($F9) -> 0 | M9: =IFERROR($L9/$K9,0) -> 0 | N9: =IF($F9="","",IFERROR($F9/'SETUP & TARGETS'!$C7,0)) -> 0 | O9: =IF(OR($C9<>"Y",COUNT($D9,$E9,$H9,$I9)=0),"",MAX(0,IFERROR(('SETUP & TARGETS'!$C$10-N($I9))/'SETUP & TARGETS'!$C$10,0))) -> 0 | P9: =IF($K9=0,"",IF($M9>='SETUP & TARGETS'!$C11,"GREEN",IF($M9>='SETUP & TARGETS'!$C13,"AMBER","RED"))) -> RED | Q9: =IFERROR(INDEX('DELAY CODE REGISTER'!$C$6:$C$49,MATCH(G9,'DELAY CODE REGISTER'!$B$6:$B$49,0)),"") -> Breakdown:Component change out
B10: 46269 | C10: Y | D10: 10165 | E10: 10165 | F10: =IF(OR($E10="",$D10=""),"",MAX(0,$E10-$D10)) -> 0 | G10: BD-CC | I10: 18 | J10: =IF($C10="Y",'SETUP & TARGETS'!$C$7,0) -> 18 | K10: =$K9+$J10 -> 72 | L10: =$L9+N($F10) -> 0 | M10: =IFERROR($L10/$K10,0) -> 0 | N10: =IF($F10="","",IFERROR($F10/'SETUP & TARGETS'!$C7,0)) -> 0 | O10: =IF(OR($C10<>"Y",COUNT($D10,$E10,$H10,$I10)=0),"",MAX(0,IFERROR(('SETUP & TARGETS'!$C$10-N($I10))/'SETUP & TARGETS'!$C$10,0))) -> 0 | P10: =IF($K10=0,"",IF($M10>='SETUP & TARGETS'!$C11,"GREEN",IF($M10>='SETUP & TARGETS'!$C13,"AMBER","RED"))) -> RED | Q10: =IFERROR(INDEX('DELAY CODE REGISTER'!$C$6:$C$49,MATCH(G10,'DELAY CODE REGISTER'!$B$6:$B$49,0)),"") -> Breakdown:Component change out
B11: 46270 | C11: Y | D11: 10165 | E11: 10165 | F11: =IF(OR($E11="",$D11=""),"",MAX(0,$E11-$D11)) -> 0 | G11: BD-CC | I11: 18 | J11: =IF($C11="Y",'SETUP & TARGETS'!$C$7,0) -> 18 | K11: =$K10+$J11 -> 90 | L11: =$L10+N($F11) -> 0 | M11: =IFERROR($L11/$K11,0) -> 0 | N11: =IF($F11="","",IFERROR($F11/'SETUP & TARGETS'!$C7,0)) -> 0 | O11: =IF(OR($C11<>"Y",COUNT($D11,$E11,$H11,$I11)=0),"",MAX(0,IFERROR(('SETUP & TARGETS'!$C$10-N($I11))/'SETUP & TARGETS'!$C$10,0))) -> 0 | P11: =IF($K11=0,"",IF($M11>='SETUP & TARGETS'!$C11,"GREEN",IF($M11>='SETUP & TARGETS'!$C13,"AMBER","RED"))) -> RED | Q11: =IFERROR(INDEX('DELAY CODE REGISTER'!$C$6:$C$49,MATCH(G11,'DELAY CODE REGISTER'!$B$6:$B$49,0)),"") -> Breakdown:Component change out
B12: 46271 | C12: Y | D12: 10165 | E12: 10165 | F12: =IF(OR($E12="",$D12=""),"",MAX(0,$E12-$D12)) -> 0 | G12: BD-CC | I12: 18 | J12: =IF($C12="Y",'SETUP & TARGETS'!$C$7,0) -> 18 | K12: =$K11+$J12 -> 108 | L12: =$L11+N($F12) -> 0 | M12: =IFERROR($L12/$K12,0) -> 0 | N12: =IF($F12="","",IFERROR($F12/'SETUP & TARGETS'!$C7,0)) -> 0 | O12: =IF(OR($C12<>"Y",COUNT($D12,$E12,$H12,$I12)=0),"",MAX(0,IFERROR(('SETUP & TARGETS'!$C$10-N($I12))/'SETUP & TARGETS'!$C$10,0))) -> 0 | P12: =IF($K12=0,"",IF($M12>='SETUP & TARGETS'!$C11,"GREEN",IF($M12>='SETUP & TARGETS'!$C13,"AMBER","RED"))) -> RED | Q12: =IFERROR(INDEX('DELAY CODE REGISTER'!$C$6:$C$49,MATCH(G12,'DELAY CODE REGISTER'!$B$6:$B$49,0)),"") -> Breakdown:Component change out
B13: 46272 | C13: Y | D13: 10165 | E13: 10165 | F13: =IF(OR($E13="",$D13=""),"",MAX(0,$E13-$D13)) -> 0 | G13: BD-CC | I13: 18 | J13: =IF($C13="Y",'SETUP & TARGETS'!$C$7,0) -> 18 | K13: =$K12+$J13 -> 126 | L13: =$L12+N($F13) -> 0 | M13: =IFERROR($L13/$K13,0) -> 0 | N13: =IF($F13="","",IFERROR($F13/'SETUP & TARGETS'!$C7,0)) -> 0 | O13: =IF(OR($C13<>"Y",COUNT($D13,$E13,$H13,$I13)=0),"",MAX(0,IFERROR(('SETUP & TARGETS'!$C$10-N($I13))/'SETUP & TARGETS'!$C$10,0))) -> 0 | P13: =IF($K13=0,"",IF($M13>='SETUP & TARGETS'!$C11,"GREEN",IF($M13>='SETUP & TARGETS'!$C13,"AMBER","RED"))) -> RED | Q13: =IFERROR(INDEX('DELAY CODE REGISTER'!$C$6:$C$49,MATCH(G13,'DELAY CODE REGISTER'!$B$6:$B$49,0)),"") -> Breakdown:Component change out
B14: 46273 | C14: Y | D14: 10165 | E14: 10165 | F14: =IF(OR($E14="",$D14=""),"",MAX(0,$E14-$D14)) -> 0 | G14: BD-CC | I14: 18 | J14: =IF($C14="Y",'SETUP & TARGETS'!$C$7,0) -> 18 | K14: =$K13+$J14 -> 144 | L14: =$L13+N($F14) -> 0 | M14: =IFERROR($L14/$K14,0) -> 0 | N14: =IF($F14="","",IFERROR($F14/'SETUP & TARGETS'!$C7,0)) -> 0 | O14: =IF(OR($C14<>"Y",COUNT($D14,$E14,$H14,$I14)=0),"",MAX(0,IFERROR(('SETUP & TARGETS'!$C$10-N($I14))/'SETUP & TARGETS'!$C$10,0))) -> 0 | P14: =IF($K14=0,"",IF($M14>='SETUP & TARGETS'!$C11,"GREEN",IF($M14>='SETUP & TARGETS'!$C13,"AMBER","RED"))) -> RED | Q14: =IFERROR(INDEX('DELAY CODE REGISTER'!$C$6:$C$49,MATCH(G14,'DELAY CODE REGISTER'!$B$6:$B$49,0)),"") -> Breakdown:Component change out
B15: 46274 | C15: Y | D15: 10165 | E15: 10165 | F15: =IF(OR($E15="",$D15=""),"",MAX(0,$E15-$D15)) -> 0 | G15: BD-CC | I15: 18 | J15: =IF($C15="Y",'SETUP & TARGETS'!$C$7,0) -> 18 | K15: =$K14+$J15 -> 162 | L15: =$L14+N($F15) -> 0 | M15: =IFERROR($L15/$K15,0) -> 0 | N15: =IF($F15="","",IFERROR($F15/'SETUP & TARGETS'!$C7,0)) -> 0 | O15: =IF(OR($C15<>"Y",COUNT($D15,$E15,$H15,$I15)=0),"",MAX(0,IFERROR(('SETUP & TARGETS'!$C$10-N($I15))/'SETUP & TARGETS'!$C$10,0))) -> 0 | P15: =IF($K15=0,"",IF($M15>='SETUP & TARGETS'!$C11,"GREEN",IF($M15>='SETUP & TARGETS'!$C13,"AMBER","RED"))) -> RED | Q15: =IFERROR(INDEX('DELAY CODE REGISTER'!$C$6:$C$49,MATCH(G15,'DELAY CODE REGISTER'!$B$6:$B$49,0)),"") -> Breakdown:Component change out
B16: 46275 | C16: Y | D16: 10165 | E16: 10165 | F16: =IF(OR($E16="",$D16=""),"",MAX(0,$E16-$D16)) -> 0 | G16: BD-CC | I16: 18 | J16: =IF($C16="Y",'SETUP & TARGETS'!$C$7,0) -> 18 | K16: =$K15+$J16 -> 180 | L16: =$L15+N($F16) -> 0 | M16: =IFERROR($L16/$K16,0) -> 0 | N16: =IF($F16="","",IFERROR($F16/'SETUP & TARGETS'!$C7,0)) -> 0 | O16: =IF(OR($C16<>"Y",COUNT($D16,$E16,$H16,$I16)=0),"",MAX(0,IFERROR(('SETUP & TARGETS'!$C$10-N($I16))/'SETUP & TARGETS'!$C$10,0))) -> 0 | P16: =IF($K16=0,"",IF($M16>='SETUP & TARGETS'!$C11,"GREEN",IF($M16>='SETUP & TARGETS'!$C13,"AMBER","RED"))) -> RED | Q16: =IFERROR(INDEX('DELAY CODE REGISTER'!$C$6:$C$49,MATCH(G16,'DELAY CODE REGISTER'!$B$6:$B$49,0)),"") -> Breakdown:Component change out
B17: 46276 | C17: Y | D17: 10165 | E17: 10165 | F17: =IF(OR($E17="",$D17=""),"",MAX(0,$E17-$D17)) -> 0 | G17: BD-CC | I17: 18 | J17: =IF($C17="Y",'SETUP & TARGETS'!$C$7,0) -> 18 | K17: =$K16+$J17 -> 198 | L17: =$L16+N($F17) -> 0 | M17: =IFERROR($L17/$K17,0) -> 0 | N17: =IF($F17="","",IFERROR($F17/'SETUP & TARGETS'!$C7,0)) -> 0 | O17: =IF(OR($C17<>"Y",COUNT($D17,$E17,$H17,$I17)=0),"",MAX(0,IFERROR(('SETUP & TARGETS'!$C$10-N($I17))/'SETUP & TARGETS'!$C$10,0))) -> 0 | P17: =IF($K17=0,"",IF($M17>='SETUP & TARGETS'!$C11,"GREEN",IF($M17>='SETUP & TARGETS'!$C13,"AMBER","RED"))) -> RED | Q17: =IFERROR(INDEX('DELAY CODE REGISTER'!$C$6:$C$49,MATCH(G17,'DELAY CODE REGISTER'!$B$6:$B$49,0)),"") -> Breakdown:Component change out
B18: 46277 | C18: Y | D18: 10165 | E18: 10165 | F18: =IF(OR($E18="",$D18=""),"",MAX(0,$E18-$D18)) -> 0 | G18: BD-CC | I18: 18 | J18: =IF($C18="Y",'SETUP & TARGETS'!$C$7,0) -> 18 | K18: =$K17+$J18 -> 216 | L18: =$L17+N($F18) -> 0 | M18: =IFERROR($L18/$K18,0) -> 0 | N18: =IF($F18="","",IFERROR($F18/'SETUP & TARGETS'!$C7,0)) -> 0 | O18: =IF(OR($C18<>"Y",COUNT($D18,$E18,$H18,$I18)=0),"",MAX(0,IFERROR(('SETUP & TARGETS'!$C$10-N($I18))/'SETUP & TARGETS'!$C$10,0))) -> 0 | P18: =IF($K18=0,"",IF($M18>='SETUP & TARGETS'!$C11,"GREEN",IF($M18>='SETUP & TARGETS'!$C13,"AMBER","RED"))) -> RED | Q18: =IFERROR(INDEX('DELAY CODE REGISTER'!$C$6:$C$49,MATCH(G18,'DELAY CODE REGISTER'!$B$6:$B$49,0)),"") -> Breakdown:Component change out
B19: 46278 | C19: Y | D19: 10165 | E19: 10165 | F19: =IF(OR($E19="",$D19=""),"",MAX(0,$E19-$D19)) -> 0 | G19: BD-CC | I19: 18 | J19: =IF($C19="Y",'SETUP & TARGETS'!$C$7,0) -> 18 | K19: =$K18+$J19 -> 234 | L19: =$L18+N($F19) -> 0 | M19: =IFERROR($L19/$K19,0) -> 0 | N19: =IF($F19="","",IFERROR($F19/'SETUP & TARGETS'!$C7,0)) -> 0 | O19: =IF(OR($C19<>"Y",COUNT($D19,$E19,$H19,$I19)=0),"",MAX(0,IFERROR(('SETUP & TARGETS'!$C$10-N($I19))/'SETUP & TARGETS'!$C$10,0))) -> 0 | P19: =IF($K19=0,"",IF($M19>='SETUP & TARGETS'!$C11,"GREEN",IF($M19>='SETUP & TARGETS'!$C13,"AMBER","RED"))) -> RED | Q19: =IFERROR(INDEX('DELAY CODE REGISTER'!$C$6:$C$49,MATCH(G19,'DELAY CODE REGISTER'!$B$6:$B$49,0)),"") -> Breakdown:Component change out
B20: 46279 | C20: Y | D20: 10165 | E20: 10165 | F20: =IF(OR($E20="",$D20=""),"",MAX(0,$E20-$D20)) -> 0 | G20: BD-CC | I20: 18 | J20: =IF($C20="Y",'SETUP & TARGETS'!$C$7,0) -> 18 | K20: =$K19+$J20 -> 252 | L20: =$L19+N($F20) -> 0 | M20: =IFERROR($L20/$K20,0) -> 0 | N20: =IF($F20="","",IFERROR($F20/'SETUP & TARGETS'!$C7,0)) -> 0 | O20: =IF(OR($C20<>"Y",COUNT($D20,$E20,$H20,$I20)=0),"",MAX(0,IFERROR(('SETUP & TARGETS'!$C$10-N($I20))/'SETUP & TARGETS'!$C$10,0))) -> 0 | P20: =IF($K20=0,"",IF($M20>='SETUP & TARGETS'!$C11,"GREEN",IF($M20>='SETUP & TARGETS'!$C13,"AMBER","RED"))) -> RED | Q20: =IFERROR(INDEX('DELAY CODE REGISTER'!$C$6:$C$49,MATCH(G20,'DELAY CODE REGISTER'!$B$6:$B$49,0)),"") -> Breakdown:Component change out
B21: 46280 | C21: Y | D21: 10165 | E21: 10165 | F21: =IF(OR($E21="",$D21=""),"",MAX(0,$E21-$D21)) -> 0 | G21: BD-CC | I21: 18 | J21: =IF($C21="Y",'SETUP & TARGETS'!$C$7,0) -> 18 | K21: =$K20+$J21 -> 270 | L21: =$L20+N($F21) -> 0 | M21: =IFERROR($L21/$K21,0) -> 0 | N21: =IF($F21="","",IFERROR($F21/'SETUP & TARGETS'!$C7,0)) -> 0 | O21: =IF(OR($C21<>"Y",COUNT($D21,$E21,$H21,$I21)=0),"",MAX(0,IFERROR(('SETUP & TARGETS'!$C$10-N($I21))/'SETUP & TARGETS'!$C$10,0))) -> 0 | P21: =IF($K21=0,"",IF($M21>='SETUP & TARGETS'!$C11,"GREEN",IF($M21>='SETUP & TARGETS'!$C13,"AMBER","RED"))) -> RED | Q21: =IFERROR(INDEX('DELAY CODE REGISTER'!$C$6:$C$49,MATCH(G21,'DELAY CODE REGISTER'!$B$6:$B$49,0)),"") -> Breakdown:Component change out
B22: 46281 | C22: Y | F22: =IF(OR($E22="",$D22=""),"",MAX(0,$E22-$D22)) | J22: =IF($C22="Y",'SETUP & TARGETS'!$C$7,0) -> 18 | K22: =$K21+$J22 -> 288 | L22: =$L21+N($F22) -> 0 | M22: =IFERROR($L22/$K22,0) -> 0 | N22: =IF($F22="","",IFERROR($F22/'SETUP & TARGETS'!$C7,0)) | O22: =IF(OR($C22<>"Y",COUNT($D22,$E22,$H22,$I22)=0),"",MAX(0,IFERROR(('SETUP & TARGETS'!$C$10-N($I22))/'SETUP & TARGETS'!$C$10,0))) | P22: =IF($K22=0,"",IF($M22>='SETUP & TARGETS'!$C11,"GREEN",IF($M22>='SETUP & TARGETS'!$C13,"AMBER","RED"))) -> RED | Q22: =IFERROR(INDEX('DELAY CODE REGISTER'!$C$6:$C$49,MATCH(G22,'DELAY CODE REGISTER'!$B$6:$B$49,0)),"")
B23: 46282 | C23: Y | F23: =IF(OR($E23="",$D23=""),"",MAX(0,$E23-$D23)) | J23: =IF($C23="Y",'SETUP & TARGETS'!$C$7,0) -> 18 | K23: =$K22+$J23 -> 306 | L23: =$L22+N($F23) -> 0 | M23: =IFERROR($L23/$K23,0) -> 0 | N23: =IF($F23="","",IFERROR($F23/'SETUP & TARGETS'!$C7,0)) | O23: =IF(OR($C23<>"Y",COUNT($D23,$E23,$H23,$I23)=0),"",MAX(0,IFERROR(('SETUP & TARGETS'!$C$10-N($I23))/'SETUP & TARGETS'!$C$10,0))) | P23: =IF($K23=0,"",IF($M23>='SETUP & TARGETS'!$C11,"GREEN",IF($M23>='SETUP & TARGETS'!$C13,"AMBER","RED"))) -> RED | Q23: =IFERROR(INDEX('DELAY CODE REGISTER'!$C$6:$C$49,MATCH(G23,'DELAY CODE REGISTER'!$B$6:$B$49,0)),"")
B24: 46283 | C24: Y | F24: =IF(OR($E24="",$D24=""),"",MAX(0,$E24-$D24)) | J24: =IF($C24="Y",'SETUP & TARGETS'!$C$7,0) -> 18 | K24: =$K23+$J24 -> 324 | L24: =$L23+N($F24) -> 0 | M24: =IFERROR($L24/$K24,0) -> 0 | N24: =IF($F24="","",IFERROR($F24/'SETUP & TARGETS'!$C7,0)) | O24: =IF(OR($C24<>"Y",COUNT($D24,$E24,$H24,$I24)=0),"",MAX(0,IFERROR(('SETUP & TARGETS'!$C$10-N($I24))/'SETUP & TARGETS'!$C$10,0))) | P24: =IF($K24=0,"",IF($M24>='SETUP & TARGETS'!$C11,"GREEN",IF($M24>='SETUP & TARGETS'!$C13,"AMBER","RED"))) -> RED | Q24: =IFERROR(INDEX('DELAY CODE REGISTER'!$C$6:$C$49,MATCH(G24,'DELAY CODE REGISTER'!$B$6:$B$49,0)),"")
B25: 46284 | C25: Y | F25: =IF(OR($E25="",$D25=""),"",MAX(0,$E25-$D25)) | J25: =IF($C25="Y",'SETUP & TARGETS'!$C$7,0) -> 18 | K25: =$K24+$J25 -> 342 | L25: =$L24+N($F25) -> 0 | M25: =IFERROR($L25/$K25,0) -> 0 | N25: =IF($F25="","",IFERROR($F25/'SETUP & TARGETS'!$C7,0)) | O25: =IF(OR($C25<>"Y",COUNT($D25,$E25,$H25,$I25)=0),"",MAX(0,IFERROR(('SETUP & TARGETS'!$C$10-N($I25))/'SETUP & TARGETS'!$C$10,0))) | P25: =IF($K25=0,"",IF($M25>='SETUP & TARGETS'!$C11,"GREEN",IF($M25>='SETUP & TARGETS'!$C13,"AMBER","RED"))) -> RED | Q25: =IFERROR(INDEX('DELAY CODE REGISTER'!$C$6:$C$49,MATCH(G25,'DELAY CODE REGISTER'!$B$6:$B$49,0)),"")
B26: 46285 | C26: Y | F26: =IF(OR($E26="",$D26=""),"",MAX(0,$E26-$D26)) | J26: =IF($C26="Y",'SETUP & TARGETS'!$C$7,0) -> 18 | K26: =$K25+$J26 -> 360 | L26: =$L25+N($F26) -> 0 | M26: =IFERROR($L26/$K26,0) -> 0 | N26: =IF($F26="","",IFERROR($F26/'SETUP & TARGETS'!$C7,0)) | O26: =IF(OR($C26<>"Y",COUNT($D26,$E26,$H26,$I26)=0),"",MAX(0,IFERROR(('SETUP & TARGETS'!$C$10-N($I26))/'SETUP & TARGETS'!$C$10,0))) | P26: =IF($K26=0,"",IF($M26>='SETUP & TARGETS'!$C11,"GREEN",IF($M26>='SETUP & TARGETS'!$C13,"AMBER","RED"))) -> RED | Q26: =IFERROR(INDEX('DELAY CODE REGISTER'!$C$6:$C$49,MATCH(G26,'DELAY CODE REGISTER'!$B$6:$B$49,0)),"")
B27: 46286 | C27: Y | F27: =IF(OR($E27="",$D27=""),"",MAX(0,$E27-$D27)) | J27: =IF($C27="Y",'SETUP & TARGETS'!$C$7,0) -> 18 | K27: =$K26+$J27 -> 378 | L27: =$L26+N($F27) -> 0 | M27: =IFERROR($L27/$K27,0) -> 0 | N27: =IF($F27="","",IFERROR($F27/'SETUP & TARGETS'!$C7,0)) | O27: =IF(OR($C27<>"Y",COUNT($D27,$E27,$H27,$I27)=0),"",MAX(0,IFERROR(('SETUP & TARGETS'!$C$10-N($I27))/'SETUP & TARGETS'!$C$10,0))) | P27: =IF($K27=0,"",IF($M27>='SETUP & TARGETS'!$C11,"GREEN",IF($M27>='SETUP & TARGETS'!$C13,"AMBER","RED"))) -> RED | Q27: =IFERROR(INDEX('DELAY CODE REGISTER'!$C$6:$C$49,MATCH(G27,'DELAY CODE REGISTER'!$B$6:$B$49,0)),"")
B28: 46287 | C28: Y | F28: =IF(OR($E28="",$D28=""),"",MAX(0,$E28-$D28)) | J28: =IF($C28="Y",'SETUP & TARGETS'!$C$7,0) -> 18 | K28: =$K27+$J28 -> 396 | L28: =$L27+N($F28) -> 0 | M28: =IFERROR($L28/$K28,0) -> 0 | N28: =IF($F28="","",IFERROR($F28/'SETUP & TARGETS'!$C7,0)) | O28: =IF(OR($C28<>"Y",COUNT($D28,$E28,$H28,$I28)=0),"",MAX(0,IFERROR(('SETUP & TARGETS'!$C$10-N($I28))/'SETUP & TARGETS'!$C$10,0))) | P28: =IF($K28=0,"",IF($M28>='SETUP & TARGETS'!$C11,"GREEN",IF($M28>='SETUP & TARGETS'!$C13,"AMBER","RED"))) -> RED | Q28: =IFERROR(INDEX('DELAY CODE REGISTER'!$C$6:$C$49,MATCH(G28,'DELAY CODE REGISTER'!$B$6:$B$49,0)),"")
B29: 46288 | C29: Y | F29: =IF(OR($E29="",$D29=""),"",MAX(0,$E29-$D29)) | J29: =IF($C29="Y",'SETUP & TARGETS'!$C$7,0) -> 18 | K29: =$K28+$J29 -> 414 | L29: =$L28+N($F29) -> 0 | M29: =IFERROR($L29/$K29,0) -> 0 | N29: =IF($F29="","",IFERROR($F29/'SETUP & TARGETS'!$C7,0)) | O29: =IF(OR($C29<>"Y",COUNT($D29,$E29,$H29,$I29)=0),"",MAX(0,IFERROR(('SETUP & TARGETS'!$C$10-N($I29))/'SETUP & TARGETS'!$C$10,0))) | P29: =IF($K29=0,"",IF($M29>='SETUP & TARGETS'!$C11,"GREEN",IF($M29>='SETUP & TARGETS'!$C13,"AMBER","RED"))) -> RED | Q29: =IFERROR(INDEX('DELAY CODE REGISTER'!$C$6:$C$49,MATCH(G29,'DELAY CODE REGISTER'!$B$6:$B$49,0)),"")
B30: 46289 | C30: Y | F30: =IF(OR($E30="",$D30=""),"",MAX(0,$E30-$D30)) | J30: =IF($C30="Y",'SETUP & TARGETS'!$C$7,0) -> 18 | K30: =$K29+$J30 -> 432 | L30: =$L29+N($F30) -> 0 | M30: =IFERROR($L30/$K30,0) -> 0 | N30: =IF($F30="","",IFERROR($F30/'SETUP & TARGETS'!$C7,0)) | O30: =IF(OR($C30<>"Y",COUNT($D30,$E30,$H30,$I30)=0),"",MAX(0,IFERROR(('SETUP & TARGETS'!$C$10-N($I30))/'SETUP & TARGETS'!$C$10,0))) | P30: =IF($K30=0,"",IF($M30>='SETUP & TARGETS'!$C11,"GREEN",IF($M30>='SETUP & TARGETS'!$C13,"AMBER","RED"))) -> RED | Q30: =IFERROR(INDEX('DELAY CODE REGISTER'!$C$6:$C$49,MATCH(G30,'DELAY CODE REGISTER'!$B$6:$B$49,0)),"")
B31: 46290 | C31: Y | F31: =IF(OR($E31="",$D31=""),"",MAX(0,$E31-$D31)) | J31: =IF($C31="Y",'SETUP & TARGETS'!$C$7,0) -> 18 | K31: =$K30+$J31 -> 450 | L31: =$L30+N($F31) -> 0 | M31: =IFERROR($L31/$K31,0) -> 0 | N31: =IF($F31="","",IFERROR($F31/'SETUP & TARGETS'!$C7,0)) | O31: =IF(OR($C31<>"Y",COUNT($D31,$E31,$H31,$I31)=0),"",MAX(0,IFERROR(('SETUP & TARGETS'!$C$10-N($I31))/'SETUP & TARGETS'!$C$10,0))) | P31: =IF($K31=0,"",IF($M31>='SETUP & TARGETS'!$C11,"GREEN",IF($M31>='SETUP & TARGETS'!$C13,"AMBER","RED"))) -> RED | Q31: =IFERROR(INDEX('DELAY CODE REGISTER'!$C$6:$C$49,MATCH(G31,'DELAY CODE REGISTER'!$B$6:$B$49,0)),"")
